Workbook
Name Slicer_Diabetes_Status1: #N/A
Name Slicer_Weight_Status: #N/A

Sheet splitting columns
A1: Customer ID | B1: Title | C1: First name | D1: Last name
A2: Id1 | B2: Ms. | C2: Kelly | D2: Hawks
A3: Id2 | B3: Mr. | C3: Matthew D | D3: Lehner
A4: Id3 | B4: Mr. | C4: Phil | D4: Lu
A5: Id4 | B5: Ms. | C5: Kelsey | D5: Osborne
A6: Id5 | B6: Ms. | C6: Kristyn | D6: Kadala
A7: Id6 | B7: Mr. | C7: Russell B. | D7: Baker
A8: Id7 | B8: Mr. | C8: Scott | D8: Macpherson
A9: Id8 | B9: Mr. | C9: Stephen | D9: Hallman
A10: Id9 | B10: Mr. | C10: Patrick R. | D10: Moran
A11: Id10 | B11: Ms. | C11: Brooke N. | D11: Benner
A12: Id11 | B12: Ms. | C12: Paola Andrea | D12: Fierro Vargas
... A2336: Id2335 | B2336: Mr. | C2336: Aaron K | D2336: German

Sheet Customer Names
A1: Customer ID | B1: name
A2: Id1 | B2: Hawks, Ms. Kelly
A3: Id2 | B3: Lehner, Mr. Matthew D
A4: Id3 | B4: Lu, Mr. Phil
A5: Id4 | B5: Osborne, Ms. Kelsey
A6: Id5 | B6: Kadala, Ms. Kristyn
A7: Id6 | B7: Baker, Mr. Russell B.
A8: Id7 | B8: Macpherson, Mr. Scott
A9: Id8 | B9: Hallman, Mr. Stephen
A10: Id9 | B10: Moran, Mr. Patrick R.
A11: Id10 | B11: Benner, Ms. Brooke N.
A12: Id11 | B12: Fierro Vargas, Ms. Paola Andrea
... A2336: Id2335 | B2336: German, Mr. Aaron K

Sheet Medical Examinations 2
A1: Customer ID | B1: BMI | C1: Weight Status | D1: HBA1C | E1: Diabetes Status | F1: Heart Issues | G1: Any Transplants | H1: Cancer history | I1: NumberOfMajorSurgeries | J1: smoker
A2: Id1 | B2: 47.41 | C2: Obesity | D2: 7.47 | E2: Diabetes | F2: No | G2: No | H2: No | I2: 0 | J2: Yes
A3: Id2 | B3: 30.36 | C3: Obesity | D3: 5.77 | E3: Prediabetes | F3: No | G3: No | H3: No | I3: 0 | J3: Yes
A4: Id3 | B4: 34.485 | C4: Obesity | D4: 11.87 | E4: Diabetes | F4: Yes | G4: No | H4: No | I4: 2 | J4: Yes
A5: Id4 | B5: 38.095 | C5: Obesity | D5: 6.05 | E5: Prediabetes | F5: No | G5: No | H5: No | I5: 0 | J5: Yes
A6: Id5 | B6: 35.53 | C6: Obesity | D6: 5.45 | E6: Normal | F6: No | G6: No | H6: No | I6: 0 | J6: Yes
A7: Id6 | B7: 32.8 | C7: Obesity | D7: 6.59 | E7: Diabetes | F7: No | G7: No | H7: No | I7: 0 | J7: Yes
A8: Id7 | B8: 36.4 | C8: Obesity | D8: 6.07 | E8: Prediabetes | F8: No | G8: No | H8: No | I8: 0 | J8: Yes
A9: Id8 | B9: 36.96 | C9: Obesity | D9: 7.93 | E9: Diabetes | F9: No | G9: No | H9: No | I9: 3 | J9: Yes
A10: Id9 | B10: 41.14 | C10: Obesity | D10: 9.58 | E10: Diabetes | F10: Yes | G10: No | H10: Yes | I10: 1 | J10: Yes
A11: Id10 | B11: 38.06 | C11: Obesity | D11: 10.79 | E11: Diabetes | F11: No | G11: No | H11: No | I11: 0 | J11: Yes
A12: Id11 | B12: 37.7 | C12: Obesity | D12: 5.96 | E12: Prediabetes | F12: Yes | G12: No | H12: No | I12: 2 | J12: Yes
A13: Id12 | B13: 42.13 | C13: Obesity | D13: 11.9 | E13: Diabetes | F13: No | G13: No | H13: No | I13: 0 | J13: Yes
... A2336: Id2335 | B2336: 17.58 | C2336: Underweight | D2336: 4.51 | E2336: Normal | F2336: No | G2336: No | H2336: No | I2336: 1 | J2336: No

Sheet Medical Examinations
A1: Customer ID | B1: BMI | C1: HBA1C | D1: Heart Issues | E1: Any Transplants | F1: Cancer history | G1: NumberOfMajorSurgeries | H1: smoker | K1: Data Cleaning:
A2: Id1 | B2: 47.41 | C2: 7.47 | D2: No | E2: No | F2: No | G2: No major surgery | H2: yes | K2: 1) | L2: =COUNTIF(A2:H2336,"?") -> 0
A3: Id2 | B3: 30.36 | C3: 5.77 | D3: No | E3: No | F3: No | G3: No major surgery | H3: yes
A4: Id3 | B4: 34.485 | C4: 11.87 | D4: yes | E4: No | F4: No | G4: 2 | H4: yes | J4: yes | K4: =COUNTIF(H2:H2336,"yes") -> 488
A5: Id4 | B5: 38.095 | C5: 6.05 | D5: No | E5: No | F5: No | G5: No major surgery | H5: yes | J5: no | K5: =COUNTIF(H2:H2336,"no") -> 1847
A6: Id5 | B6: 35.53 | C6: 5.45 | D6: No | E6: No | F6: No | G6: No major surgery | H6: yes
A7: Id6 | B7: 32.8 | C7: 6.59 | D7: No | E7: No | F7: No | G7: No major surgery | H7: yes
A8: Id7 | B8: 36.4 | C8: 6.07 | D8: No | E8: No | F8: No | G8: No major surgery | H8: yes
A9: Id8 | B9: 36.96 | C9: 7.93 | D9: No | E9: No | F9: No | G9: 3 | H9: yes
A10: Id9 | B10: 41.14 | C10: 9.58 | D10: yes | E10: No | F10: Yes | G10: 1 | H10: yes
A11: Id10 | B11: 38.06 | C11: 10.79 | D11: No | E11: No | F11: No | G11: No major surgery | H11: yes
A12: Id11 | B12: 37.7 | C12: 5.96 | D12: yes | E12: No | F12: No | G12: 2 | H12: yes
A13: Id12 | B13: 42.13 | C13: 11.9 | D13: No | E13: No | F13: No | G13: No major surgery | H13: yes
A14: Id13 | B14: 40.92 | C14: 8.41 | D14: No | E14: No | F14: No | G14: No major surgery | H14: yes
A15: Id14 | B15: 40.565 | C15: 7.02 | D15: No | E15: No | F15: No | G15: No major surgery | H15: yes
A16: Id15 | B16: 36.385 | C16: 7.59 | D16: yes | E16: No | F16: No | G16: 2 | H16: yes
A17: Id16 | B17: 39.9 | C17: 11.32 | D17: No | E17: No | F17: No | G17: No major surgery | H17: yes
A18: Id17 | B18: 33.8 | C18: 7.67 | D18: No | E18: No | F18: No | G18: 3 | H18: yes
A19: Id18 | B19: 36.765 | C19: 7.29 | D19: yes | E19: No | F19: Yes | G19: 1 | H19: yes
A20: Id19 | B20: 36.955 | C20: 4.72 | D20: yes | E20: No | F20: No | G20: 1 | H20: yes
A21: Id20 | B21: 42.9 | C21: 11.41 | D21: No | E21: No | F21: No | G21: No major surgery | H21: yes
A22: Id21 | B22: 36.3 | C22: 11.5 | D22: yes | E22: No | F22: No | G22: 2 | H22: yes
A23: Id22 | B23: 32.2 | C23: 6.22 | D23: yes | E23: No | F23: No | G23: 2 | H23: yes
A24: Id23 | B24: 31.3 | C24: 11.38 | D24: No | E24: No | F24: No | G24: 3 | H24: yes
A25: Id24 | B25: 41.8 | C25: 7.89 | D25: yes | E25: No | F25: No | G25: 2 | H25: yes
A26: Id25 | B26: 35.09 | C26: 4.38 | D26: yes | E26: No | F26: No | G26: 2 | H26: yes
A27: Id26 | B27: 33.88 | C27: 7.01 | D27: No | E27: No | F27: No | G27: 3 | H27: yes
A28: Id27 | B28: 30.875 | C28: 11.88 | D28: No | E28: No | F28: No | G28: No major surgery | H28: yes
A29: Id28 | B29: 36.86 | C29: 5.19 | D29: yes | E29: No | F29: Yes | G29: 1 | H29: yes
A30: Id29 | B30: 35.86 | C30: 6.74 | D30: yes | E30: No | F30: No | G30: 2 | H30: yes
A31: Id30 | B31: 37.05 | C31: 8.44 | D31: No | E31: No | F31: No | G31: No major surgery | H31: yes
A32: Id31 | B32: 43.89 | C32: 8.71 | D32: No | E32: No | F32: No | G32: No major surgery | H32: yes
A33: Id32 | B33: 42.35 | C33: 5.08 | D33: yes | E33: No | F33: No | G33: No major surgery | H33: yes
A34: Id33 | B34: 31.35 | C34: 6.86 | D34: No | E34: No | F34: No | G34: No major surgery | H34: yes
A35: Id34 | B35: 47.6 | C35: 5.95 | D35: yes | E35: No | F35: No | G35: No major surgery | H35: yes
A36: Id35 | B36: 46.2 | C36: 6.09 | D36: No | E36: No | F36: Yes | G36: 1 | H36: yes
A37: Id36 | B37: 32.015 | C37: 11.75 | D37: No | E37: No | F37: No | G37: No major surgery | H37: yes
A38: Id37 | B38: 40.565 | C38: 7.37 | D38: No | E38: No | F38: No | G38: No major surgery | H38: yes
A39: Id38 | B39: 32.45 | C39: 11.91 | D39: No | E39: No | F39: No | G39: No major surgery | H39: yes
A40: Id39 | B40: 34.96 | C40: 6.52 | D40: No | E40: No | F40: No | G40: No major surgery | H40: yes
...

Sheet Hospitalisation Details 2
A1: Customer ID | B1: Date Of Birth | C1: Age | D1: children | E1: charges | F1: Hospital tier | G1: City tier | H1: State ID
A2: Id2335 | B2: 33794 | C2: =DATEDIF(Table5_1[[#This Row],[Date Of Birth]],DATE(2023,6,8),"y") -> 30 | D2: 0 | E2: 563.84 | F2: tier - 2 | G2: tier - 3 | H2: R1013
A3: Id2334 | B3: 33938 | C3: =DATEDIF(Table5_1[[#This Row],[Date Of Birth]],DATE(2023,6,8),"y") -> 30 | D3: 0 | E3: 570.62 | F3: tier - 2 | G3: tier - 1 | H3: R1013
A4: Id2333 | B4: 34150 | C4: =DATEDIF(Table5_1[[#This Row],[Date Of Birth]],DATE(2023,6,8),"y") -> 29 | D4: 0 | E4: 600 | F4: tier - 2 | G4: tier - 1 | H4: R1013
A5: Id2332 | B5: 33860 | C5: =DATEDIF(Table5_1[[#This Row],[Date Of Birth]],DATE(2023,6,8),"y") -> 30 | D5: 0 | E5: 604.54 | F5: tier - 3 | G5: tier - 3 | H5: R1013
A6: Id2331 | B6: 36003 | C6: =DATEDIF(Table5_1[[#This Row],[Date Of Birth]],DATE(2023,6,8),"y") -> 24 | D6: 0 | E6: 637.26 | F6: tier - 3 | G6: tier - 3 | H6: R1013
A7: Id2330 | B7: 37215 | C7: =DATEDIF(Table5_1[[#This Row],[Date Of Birth]],DATE(2023,6,8),"y") -> 21 | D7: 0 | E7: 646.14 | F7: tier - 3 | G7: tier - 3 | H7: R1012
A8: Id2329 | B8: 34121 | C8: =DATEDIF(Table5_1[[#This Row],[Date Of Birth]],DATE(2023,6,8),"y") -> 30 | D8: 0 | E8: 650 | F8: tier - 3 | G8: tier - 3 | H8: R1013
A9: Id2328 | B9: 34884 | C9: =DATEDIF(Table5_1[[#This Row],[Date Of Birth]],DATE(2023,6,8),"y") -> 27 | D9: 0 | E9: 650 | F9: tier - 3 | G9: tier - 3 | H9: R1013
A10: Id2327 | B10: 37589 | C10: =DATEDIF(Table5_1[[#This Row],[Date Of Birth]],DATE(2023,6,8),"y") -> 20 | D10: 0 | E10: 668 | F10: tier - 3 | G10: tier - 2 | H10: R1012
A11: Id2326 | B11: 35743 | C11: =DATEDIF(Table5_1[[#This Row],[Date Of Birth]],DATE(2023,6,8),"y") -> 25 | D11: 0 | E11: 670 | F11: tier - 3 | G11: tier - 3 | H11: R1013
A12: Id2325 | B12: 37146 | C12: =DATEDIF(Table5_1[[#This Row],[Date Of Birth]],DATE(2023,6,8),"y") -> 21 | D12: 0 | E12: 687.54 | F12: tier - 3 | G12: tier - 2 | H12: R1013
A13: Id2324 | B13: 36520 | C13: =DATEDIF(Table5_1[[#This Row],[Date Of Birth]],DATE(2023,6,8),"y") -> 23 | D13: 0 | E13: 700 | F13: tier - 2 | G13: tier - 3 | H13: R1013
... A2344: Id1 | B2344: 25123 | C2344: =DATEDIF(Table5_1[[#This Row],[Date Of Birth]],DATE(2023,6,8),"y") -> 54 | D2344: 0 | E2344: 63770.43 | F2344: tier - 1 | G2344: tier - 3 | H2344: R1013

Sheet using pie chart
A3: Count of Customer ID | B3: Column Labels
A4: Row Labels | B4: No | C4: Yes | D4: Grand Total
A5: No | B5: 1540 | C5: 307 | D5: 1847
A6: Yes | B6: 404 | C6: 84 | D6: 488
A7: Grand Total | B7: 1944 | C7: 391 | D7: 2335
A15: Row Labels | B15: Sum of NumberOfMajorSurgeries | C15: Average of HBA1C
A16: No | B16: 1417 | C16: 6.6704427
A17: Yes | B17: 162 | C17: 5.1876389
A18: Grand Total | B18: 1579 | C18: 6.5789979

Sheet using column chart
A3: Average of charges | B3: Column Labels
A4: Row Labels | B4: Diabetes | C4: Normal | D4: Prediabetes | E4: Grand Total
A5: Normalweight | B5: 12509.815 | C5: 7897.0779 | D5: 10389.963 | E5: 9842.5103
A6: Obesity | B6: 19103.403 | C6: 15140.415 | D6: 15502.742 | E6: 16612.253
A7: Overweight | B7: 13886.681 | C7: 10376.643 | D7: 10008.416 | E7: 11409.791
A8: Underweight | B8: 7424.9523 | C8: 6911.0056 | D8: 5626.0918 | E8: 6899.3175
A9: Grand Total | B9: 15973.539 | C9: 12090.723 | D9: 12690.985 | E9: 13529.918
A14: Average of charges | B14: Column Labels
A15: Row Labels | B15: tier - 1 | C15: tier - 2 | D15: tier - 3 | E15: Grand Total
A16: R1011 | B16: 33081.374 | C16: 18997.281 | D16: 9250.3618 | E16: 19466.246
A17: R1017 | B17: 34070.596 | C17: 11365.622 | D17: 8667.3662 | E17: 14806.108
A18: R1015 | B18: 21523.52 | C18: 15675.543 | D18: 7570.755 | E18: 13948.61
A19: R1023 | B19: 18261.757 | C19: 13457.095 | D19: 12785.637 | E19: 13786.149
A20: R1019 | B20: 27621.61 | C20: 8116.72 | D20: 12706.976 | E20: 13633.143
A21: R1016 | B21: 39868.616 | C21: 16075.963 | D21: 8133.0084 | E21: 13589.263
A22: R1014 | B22: 13891.86 | C22: 2395.17 | D22: 16950.485 | E22: 13478.057
A23: R1018 | B23: 33475.82 | C23: 10139.553 | D23: 12570.97 | E23: 13272.787
A24: R1024 | B24: 32732.187 | C24: 10174.346 | D24: 13360.979 | E24: 12865.149
A25: R1026 | B25: 18709.798 | C25: 11919.608 | D25: 12296.78 | E25: 12489.921
A26: R1012 | B26: 26111.458 | C26: 10334.279 | D26: 10179.942 | E26: 12016.474
A27: R1022 | C27: 10102.027 | D27: 11637.812 | E27: 10650.521
A28: R1013 | B28: 31328.102 | C28: 8439.2844 | D28: 6890.7568 | E28: 10514.94
A29: R1020 | C29: 6760.5433 | D29: 11716.453 | E29: 9238.4983
A30: R1021 | C30: 7668.1787 | D30: 11518.786 | E30: 8933.3781
A31: R1025 | C31: 6886.0368 | D31: 10510.314 | E31: 8788.7823
A32: Grand Total | B32: 30189.68 | C32: 11865.269 | D32: 9462.2693 | E32: 13523.517

Sheet Sheet2
A3: Average of BMI | B3: Sum of charges | C3: Average of HBA1C | D3: Count of Customer ID | E3: Average of Age
A4: 30.972649 | B4: 31592359 | C4: 6.5789979 | D4: 2335 | E4: 39.228694

Sheet Healthcare
A1: Customer ID | B1: First name | C1: BMI | D1: HBA1C | E1: Heart Issues | F1: Any Transplants | G1: Cancer history | H1: NumberOfMajorSurgeries | I1: smoker | J1: Weight Status | K1: Diabetes Status | L1: Date Of Birth | M1: charges | N1: Hospital tier | O1: City tier | P1: State ID | Q1: Age
A2: Id1 | B2: =VLOOKUP(A2,Table1_1[],3,FALSE) -> Kelly | C2: =VLOOKUP(A2,Table3_1[],2,FALSE) -> 47.41 | D2: =VLOOKUP(A2,Table3_1[],4,FALSE) -> 7.47 | E2: =VLOOKUP(A2,Table3_1[],6,FALSE) -> No | F2: =VLOOKUP(A2,Table3_1[],7,FALSE) -> No | G2: =VLOOKUP(A2,Table3_1[],8,FALSE) -> No | H2: =VLOOKUP(A2,Table3_1[],9,FALSE) -> 0 | I2: =VLOOKUP(A2,Table3_1[],10,FALSE) -> Yes | J2: =VLOOKUP(A2,Table3_1[],3,FALSE) -> Obesity | K2: =VLOOKUP(A2,Table3_1[],5,FALSE) -> Diabetes | L2: =VLOOKUP(A2,Table5_1[],2,FALSE) -> 25123 | M2: =VLOOKUP(A2,Table5_1[],5,FALSE) -> 63770.43 | N2: =VLOOKUP(A2,Table5_1[],6,FALSE) -> tier - 1 | O2: =VLOOKUP(A2,Table5_1[],7,FALSE) -> tier - 3 | P2: =VLOOKUP(A2,Table5_1[],8,FALSE) -> R1013 | Q2: =VLOOKUP(A2,Table5_1[],3,FALSE) -> 54
A3: Id2 | B3: =VLOOKUP(A3,Table1_1[],3,FALSE) -> Matthew D | C3: =VLOOKUP(A3,Table3_1[],2,FALSE) -> 30.36 | D3: =VLOOKUP(A3,Table3_1[],4,FALSE) -> 5.77 | E3: =VLOOKUP(A3,Table3_1[],6,FALSE) -> No | F3: =VLOOKUP(A3,Table3_1[],7,FALSE) -> No | G3: =VLOOKUP(A3,Table3_1[],8,FALSE) -> No | H3: =VLOOKUP(A3,Table3_1[],9,FALSE) -> 0 | I3: =VLOOKUP(A3,Table3_1[],10,FALSE) -> Yes | J3: =VLOOKUP(A3,Table3_1[],3,FALSE) -> Obesity | K3: =VLOOKUP(A3,Table3_1[],5,FALSE) -> Prediabetes | L3: =VLOOKUP(A3,Table5_1[],2,FALSE) -> 28284 | M3: =VLOOKUP(A3,Table5_1[],5,FALSE) -> 62592.87 | N3: =VLOOKUP(A3,Table5_1[],6,FALSE) -> tier - 2 | O3: =VLOOKUP(A3,Table5_1[],7,FALSE) -> tier - 3 | P3: =VLOOKUP(A3,Table5_1[],8,FALSE) -> R1013 | Q3: =VLOOKUP(A3,Table5_1[],3,FALSE) -> 46
A4: Id3 | B4: =VLOOKUP(A4,Table1_1[],3,FALSE) -> Phil | C4: =VLOOKUP(A4,Table3_1[],2,FALSE) -> 34.485 | D4: =VLOOKUP(A4,Table3_1[],4,FALSE) -> 11.87 | E4: =VLOOKUP(A4,Table3_1[],6,FALSE) -> Yes | F4: =VLOOKUP(A4,Table3_1[],7,FALSE) -> No | G4: =VLOOKUP(A4,Table3_1[],8,FALSE) -> No | H4: =VLOOKUP(A4,Table3_1[],9,FALSE) -> 2 | I4: =VLOOKUP(A4,Table3_1[],10,FALSE) -> Yes | J4: =VLOOKUP(A4,Table3_1[],3,FALSE) -> Obesity | K4: =VLOOKUP(A4,Table3_1[],5,FALSE) -> Diabetes | L4: =VLOOKUP(A4,Table5_1[],2,FALSE) -> 25822 | M4: =VLOOKUP(A4,Table5_1[],5,FALSE) -> 60021.4 | N4: =VLOOKUP(A4,Table5_1[],6,FALSE) -> tier - 1 | O4: =VLOOKUP(A4,Table5_1[],7,FALSE) -> tier - 1 | P4: =VLOOKUP(A4,Table5_1[],8,FALSE) -> R1012 | Q4: =VLOOKUP(A4,Table5_1[],3,FALSE) -> 52
A5: Id4 | B5: =VLOOKUP(A5,Table1_1[],3,FALSE) -> Kelsey | C5: =VLOOKUP(A5,Table3_1[],2,FALSE) -> 38.095 | D5: =VLOOKUP(A5,Table3_1[],4,FALSE) -> 6.05 | E5: =VLOOKUP(A5,Table3_1[],6,FALSE) -> No | F5: =VLOOKUP(A5,Table3_1[],7,FALSE) -> No | G5: =VLOOKUP(A5,Table3_1[],8,FALSE) -> No | H5: =VLOOKUP(A5,Table3_1[],9,FALSE) -> 0 | I5: =VLOOKUP(A5,Table3_1[],10,FALSE) -> Yes | J5: =VLOOKUP(A5,Table3_1[],3,FALSE) -> Obesity | K5: =VLOOKUP(A5,Table3_1[],5,FALSE) -> Prediabetes | L5: =VLOOKUP(A5,Table5_1[],2,FALSE) -> 33395 | M5: =VLOOKUP(A5,Table5_1[],5,FALSE) -> 58571.07 | N5: =VLOOKUP(A5,Table5_1[],6,FALSE) -> tier - 1 | O5: =VLOOKUP(A5,Table5_1[],7,FALSE) -> tier - 3 | P5: =VLOOKUP(A5,Table5_1[],8,FALSE) -> R1024 | Q5: =VLOOKUP(A5,Table5_1[],3,FALSE) -> 32
A6: Id5 | B6: =VLOOKUP(A6,Table1_1[],3,FALSE) -> Kristyn | C6: =VLOOKUP(A6,Table3_1[],2,FALSE) -> 35.53 | D6: =VLOOKUP(A6,Table3_1[],4,FALSE) -> 5.45 | E6: =VLOOKUP(A6,Table3_1[],6,FALSE) -> No | F6: =VLOOKUP(A6,Table3_1[],7,FALSE) -> No | G6: =VLOOKUP(A6,Table3_1[],8,FALSE) -> No | H6: =VLOOKUP(A6,Table3_1[],9,FALSE) -> 0 | I6: =VLOOKUP(A6,Table3_1[],10,FALSE) -> Yes | J6: =VLOOKUP(A6,Table3_1[],3,FALSE) -> Obesity | K6: =VLOOKUP(A6,Table3_1[],5,FALSE) -> Normal | L6: =VLOOKUP(A6,Table5_1[],2,FALSE) -> 32678 | M6: =VLOOKUP(A6,Table5_1[],5,FALSE) -> 55135.4 | N6: =VLOOKUP(A6,Table5_1[],6,FALSE) -> tier - 1 | O6: =VLOOKUP(A6,Table5_1[],7,FALSE) -> tier - 2 | P6: =VLOOKUP(A6,Table5_1[],8,FALSE) -> R1012 | Q6: =VLOOKUP(A6,Table5_1[],3,FALSE) -> 33
A7: Id6 | B7: =VLOOKUP(A7,Table1_1[],3,FALSE) -> Russell B. | C7: =VLOOKUP(A7,Table3_1[],2,FALSE) -> 32.8 | D7: =VLOOKUP(A7,Table3_1[],4,FALSE) -> 6.59 | E7: =VLOOKUP(A7,Table3_1[],6,FALSE) -> No | F7: =VLOOKUP(A7,Table3_1[],7,FALSE) -> No | G7: =VLOOKUP(A7,Table3_1[],8,FALSE) -> No | H7: =VLOOKUP(A7,Table3_1[],9,FALSE) -> 0 | I7: =VLOOKUP(A7,Table3_1[],10,FALSE) -> Yes | J7: =VLOOKUP(A7,Table3_1[],3,FALSE) -> Obesity | K7: =VLOOKUP(A7,Table3_1[],5,FALSE) -> Diabetes | L7: =VLOOKUP(A7,Table5_1[],2,FALSE) -> 22862 | M7: =VLOOKUP(A7,Table5_1[],5,FALSE) -> 52590.83 | N7: =VLOOKUP(A7,Table5_1[],6,FALSE) -> tier - 1 | O7: =VLOOKUP(A7,Table5_1[],7,FALSE) -> tier - 3 | P7: =VLOOKUP(A7,Table5_1[],8,FALSE) -> R1011 | Q7: =VLOOKUP(A7,Table5_1[],3,FALSE) -> 60
A8: Id7 | B8: =VLOOKUP(A8,Table1_1[],3,FALSE) -> Scott | C8: =VLOOKUP(A8,Table3_1[],2,FALSE) -> 36.4 | D8: =VLOOKUP(A8,Table3_1[],4,FALSE) -> 6.07 | E8: =VLOOKUP(A8,Table3_1[],6,FALSE) -> No | F8: =VLOOKUP(A8,Table3_1[],7,FALSE) -> No | G8: =VLOOKUP(A8,Table3_1[],8,FALSE) -> No | H8: =VLOOKUP(A8,Table3_1[],9,FALSE) -> 0 | I8: =VLOOKUP(A8,Table3_1[],10,FALSE) -> Yes | J8: =VLOOKUP(A8,Table3_1[],3,FALSE) -> Obesity | K8: =VLOOKUP(A8,Table3_1[],5,FALSE) -> Prediabetes | L8: =VLOOKUP(A8,Table5_1[],2,FALSE) -> 34634 | M8: =VLOOKUP(A8,Table5_1[],5,FALSE) -> 51194.56 | N8: =VLOOKUP(A8,Table5_1[],6,FALSE) -> tier - 1 | O8: =VLOOKUP(A8,Table5_1[],7,FALSE) -> tier - 3 | P8: =VLOOKUP(A8,Table5_1[],8,FALSE) -> R1011 | Q8: =VLOOKUP(A8,Table5_1[],3,FALSE) -> 28
A9: Id8 | B9: =VLOOKUP(A9,Table1_1[],3,FALSE) -> Stephen | C9: =VLOOKUP(A9,Table3_1[],2,FALSE) -> 36.96 | D9: =VLOOKUP(A9,Table3_1[],4,FALSE) -> 7.93 | E9: =VLOOKUP(A9,Table3_1[],6,FALSE) -> No | F9: =VLOOKUP(A9,Table3_1[],7,FALSE) -> No | G9: =VLOOKUP(A9,Table3_1[],8,FALSE) -> No | H9: =VLOOKUP(A9,Table3_1[],9,FALSE) -> 3 | I9: =VLOOKUP(A9,Table3_1[],10,FALSE) -> Yes | J9: =VLOOKUP(A9,Table3_1[],3,FALSE) -> Obesity | K9: =VLOOKUP(A9,Table3_1[],5,FALSE) -> Diabetes | L9: =VLOOKUP(A9,Table5_1[],2,FALSE) -> 21363 | M9: =VLOOKUP(A9,Table5_1[],5,FALSE) -> 49577.66 | N9: =VLOOKUP(A9,Table5_1[],6,FALSE) -> tier - 2 | O9: =VLOOKUP(A9,Table5_1[],7,FALSE) -> tier - 2 | P9: =VLOOKUP(A9,Table5_1[],8,FALSE) -> R1013 | Q9: =VLOOKUP(A9,Table5_1[],3,FALSE) -> 64
A10: Id9 | B10: =VLOOKUP(A10,Table1_1[],3,FALSE) -> Patrick R. | C10: =VLOOKUP(A10,Table3_1[],2,FALSE) -> 41.14 | D10: =VLOOKUP(A10,Table3_1[],4,FALSE) -> 9.58 | E10: =VLOOKUP(A10,Table3_1[],6,FALSE) -> Yes | F10: =VLOOKUP(A10,Table3_1[],7,FALSE) -> No | G10: =VLOOKUP(A10,Table3_1[],8,FALSE) -> Yes | H10: =VLOOKUP(A10,Table3_1[],9,FALSE) -> 1 | I10: =VLOOKUP(A10,Table3_1[],10,FALSE) -> Yes | J10: =VLOOKUP(A10,Table3_1[],3,FALSE) -> Obesity | K10: =VLOOKUP(A10,Table3_1[],5,FALSE) -> Diabetes | L10: =VLOOKUP(A10,Table5_1[],2,FALSE) -> 23258 | M10: =VLOOKUP(A10,Table5_1[],5,FALSE) -> 48970.25 | N10: =VLOOKUP(A10,Table5_1[],6,FALSE) -> tier - 1 | O10: =VLOOKUP(A10,Table5_1[],7,FALSE) -> tier - 2 | P10: =VLOOKUP(A10,Table5_1[],8,FALSE) -> R1013 | Q10: =VLOOKUP(A10,Table5_1[],3,FALSE) -> 59
A11: Id10 | B11: =VLOOKUP(A11,Table1_1[],3,FALSE) -> Brooke N. | C11: =VLOOKUP(A11,Table3_1[],2,FALSE) -> 38.06 | D11: =VLOOKUP(A11,Table3_1[],4,FALSE) -> 10.79 | E11: =VLOOKUP(A11,Table3_1[],6,FALSE) -> No | F11: =VLOOKUP(A11,Table3_1[],7,FALSE) -> No | G11: =VLOOKUP(A11,Table3_1[],8,FALSE) -> No | H11: =VLOOKUP(A11,Table3_1[],9,FALSE) -> 0 | I11: =VLOOKUP(A11,Table3_1[],10,FALSE) -> Yes | J11: =VLOOKUP(A11,Table3_1[],3,FALSE) -> Obesity | K11: =VLOOKUP(A11,Table3_1[],5,FALSE) -> Diabetes | L11: =VLOOKUP(A11,Table5_1[],2,FALSE) -> 28853 | M11: =VLOOKUP(A11,Table5_1[],5,FALSE) -> 48885.14 | N11: =VLOOKUP(A11,Table5_1[],6,FALSE) -> tier - 1 | O11: =VLOOKUP(A11,Table5_1[],7,FALSE) -> tier - 2 | P11: =VLOOKUP(A11,Table5_1[],8,FALSE) -> R1013 | Q11: =VLOOKUP(A11,Table5_1[],3,FALSE) -> 44
A12: Id11 | B12: =VLOOKUP(A12,Table1_1[],3,FALSE) -> Paola Andrea | C12: =VLOOKUP(A12,Table3_1[],2,FALSE) -> 37.7 | D12: =VLOOKUP(A12,Table3_1[],4,FALSE) -> 5.96 | E12: =VLOOKUP(A12,Table3_1[],6,FALSE) -> Yes | F12: =VLOOKUP(A12,Table3_1[],7,FALSE) -> No | G12: =VLOOKUP(A12,Table3_1[],8,FALSE) -> No | H12: =VLOOKUP(A12,Table3_1[],9,FALSE) -> 2 | I12: =VLOOKUP(A12,Table3_1[],10,FALSE) -> Yes | J12: =VLOOKUP(A12,Table3_1[],3,FALSE) -> Obesity | K12: =VLOOKUP(A12,Table3_1[],5,FALSE) -> Prediabetes | L12: =VLOOKUP(A12,Table5_1[],2,FALSE) -> 21753 | M12: =VLOOKUP(A12,Table5_1[],5,FALSE) -> 48824.45 | N12: =VLOOKUP(A12,Table5_1[],6,FALSE) -> tier - 2 | O12: =VLOOKUP(A12,Table5_1[],7,FALSE) -> tier - 1 | P12: =VLOOKUP(A12,Table5_1[],8,FALSE) -> R1011 | Q12: =VLOOKUP(A12,Table5_1[],3,FALSE) -> 63
A13: Id12 | B13: =VLOOKUP(A13,Table1_1[],3,FALSE) -> David | C13: =VLOOKUP(A13,Table3_1[],2,FALSE) -> 42.13 | D13: =VLOOKUP(A13,Table3_1[],4,FALSE) -> 11.9 | E13: =VLOOKUP(A13,Table3_1[],6,FALSE) -> No | F13: =VLOOKUP(A13,Table3_1[],7,FALSE) -> No | G13: =VLOOKUP(A13,Table3_1[],8,FALSE) -> No | H13: =VLOOKUP(A13,Table3_1[],9,FALSE) -> 0 | I13: =VLOOKUP(A13,Table3_1[],10,FALSE) -> Yes | J13: =VLOOKUP(A13,Table3_1[],3,FALSE) -> Obesity | K13: =VLOOKUP(A13,Table3_1[],5,FALSE) -> Diabetes | L13: =VLOOKUP(A13,Table5_1[],2,FALSE) -> 24042 | M13: =VLOOKUP(A13,Table5_1[],5,FALSE) -> 48675.52 | N13: =VLOOKUP(A13,Table5_1[],6,FALSE) -> tier - 1 | O13: =VLOOKUP(A13,Table5_1[],7,FALSE) -> tier - 2 | P13: =VLOOKUP(A13,Table5_1[],8,FALSE) -> R1013 | Q13: =VLOOKUP(A13,Table5_1[],3,FALSE) -> 57
... A2336: Id2335 | B2336: =VLOOKUP(A2336,Table1_1[],3,FALSE) -> Aaron K | C2336: =VLOOKUP(A2336,Table3_1[],2,FALSE) -> 17.58 | D2336: =VLOOKUP(A2336,Table3_1[],4,FALSE) -> 4.51 | E2336: =VLOOKUP(A2336,Table3_1[],6,FALSE) -> No | F2336: =VLOOKUP(A2336,Table3_1[],7,FALSE) -> No | G2336: =VLOOKUP(A2336,Table3_1[],8,FALSE) -> No | H2336: =VLOOKUP(A2336,Table3_1[],9,FALSE) -> 1 | I2336: =VLOOKUP(A2336,Table3_1[],10,FALSE) -> No | J2336: =VLOOKUP(A2336,Table3_1[],3,FALSE) -> Underweight | K2336: =VLOOKUP(A2336,Table3_1[],5,FALSE) -> Normal | L2336: =VLOOKUP(A2336,Table5_1[],2,FALSE) -> 33794 | M2336: =VLOOKUP(A2336,Table5_1[],5,FALSE) -> 563.84 | N2336: =VLOOKUP(A2336,Table5_1[],6,FALSE) -> tier - 2 | O2336: =VLOOKUP(A2336,Table5_1[],7,FALSE) -> tier - 3 | P2336: =VLOOKUP(A2336,Table5_1[],8,FALSE) -> R1013 | Q2336: =VLOOKUP(A2336,Table5_1[],3,FALSE) -> 30

Sheet Dashboard
C1: HEALTHCARE ANALYSIS DASHBOARD
B5: Total patients | E5: Average age | H5: Average BMI | K5: Average HBA1C | N5: TOTAL Healthcare charges
B6: =GETPIVOTDATA("Count of Customer ID",Sheet2!$A$3) -> 2335 | E6: =GETPIVOTDATA("Average of Age",Sheet2!$A$3) -> 39.228694 | H6: =GETPIVOTDATA("Average of BMI",Sheet2!$A$3) -> 30.972649 | K6: =GETPIVOTDATA("Average of HBA1C",Sheet2!$A$3) -> 6.5789979 | N6: =GETPIVOTDATA("Sum of charges",Sheet2!$A$3) -> 31592359

Sheet Hospitalisation Details
A1: Customer ID | B1: year | C1: month | D1: date | E1: children | F1: charges | G1: Hospital tier | H1: City tier | I1: State ID | M1: Data Cleaning:
A2: Id2335 | B2: 1992 | C2: Jul | D2: 9 | E2: 0 | F2: 563.84 | G2: tier - 2 | H2: tier - 3 | I2: R1013
A3: Id2334 | B3: 1992 | C3: Nov | D3: 30 | E3: 0 | F3: 570.62 | G3: tier - 2 | H3: tier - 1 | I3: R1013 | M3: 1) Check for the number of missing values marked with '?' in each column of the “Medical
A4: Id2333 | B4: 1993 | C4: Jun | D4: 30 | E4: 0 | F4: 600 | G4: tier - 2 | H4: tier - 1 | I4: R1013 | M4: Examinations” Table and "Hospitalization Details" Table.
A5: Id2332 | B5: 1992 | C5: Sep | D5: 13 | E5: 0 | F5: 604.54 | G5: tier - 3 | H5: tier - 3 | I5: R1013
A6: Id2331 | B6: 1998 | C6: Jul | D6: 27 | E6: 0 | F6: 637.26 | G6: tier - 3 | H6: tier - 3 | I6: R1013 | M6: Columns | N6: Missing values
A7: Id2330 | B7: 2001 | C7: Nov | D7: 20 | E7: 0 | F7: 646.14 | G7: tier - 3 | H7: tier - 3 | I7: R1012 | L7: Medical examination table: | M7: smoker | N7: =COUNTIF('Medical Examinations'!H2:H2336,"?") -> 0 | O7: 2
A8: Id2329 | B8: 1993 | C8: Jun | D8: 1 | E8: 0 | F8: 650 | G8: tier - 3 | H8: tier - 3 | I8: R1013 | L8: Hospitalisation Details table: | M8: Customer ID | N8: =COUNTIF(A2:A2344,"?") -> 6 | O8: 6
A9: Id2328 | B9: 1995 | C9: Jul | D9: 4 | E9: 0 | F9: 650 | G9: tier - 3 | H9: tier - 3 | I9: R1013 | M9: year | N9: =COUNTIF(B:B,"?") -> 0 | O9: 2
A10: Id2327 | B10: 2002 | C10: Nov | D10: 29 | E10: 0 | F10: 668 | G10: tier - 3 | H10: tier - 2 | I10: R1012 | M10: month | N10: =COUNTIF(C:C,"?") -> 0 | O10: 3
A11: Id2326 | B11: 1997 | C11: Nov | D11: 9 | E11: 0 | F11: 670 | G11: tier - 3 | H11: tier - 3 | I11: R1013 | M11: date | N11: =COUNTIF(D:D,"?") -> 0
A12: Id2325 | B12: 2001 | C12: Sep | D12: 12 | E12: 0 | F12: 687.54 | G12: tier - 3 | H12: tier - 2 | I12: R1013 | M12: Hospital tier | N12: =COUNTIF(G:G,"?") -> 0 | O12: 1
A13: Id2324 | B13: 1999 | C13: Dec | D13: 26 | E13: 0 | F13: 700 | G13: tier - 2 | H13: tier - 3 | I13: R1013 | M13: City tier | N13: =COUNTIF(H:H,"?") -> 0 | O13: 1
A14: Id2323 | B14: 1999 | C14: Dec | D14: 14 | E14: 0 | F14: 722.99 | G14: tier - 3 | H14: tier - 1 | I14: R1013 | M14: State ID | N14: =COUNTIF(I:I,"?") -> 0 | O14: 2
A15: Id2322 | B15: 2002 | C15: Sep | D15: 19 | E15: 0 | F15: 750 | G15: tier - 3 | H15: tier - 1 | I15: R1012 | M15: Total | N15: =SUM(N7:N14) -> 6 | O15: 17
A16: Id2321 | B16: 1993 | C16: Aug | D16: 9 | E16: 0 | F16: 760 | G16: tier - 3 | H16: tier - 1 | I16: R1013
A17: Id2320 | B17: 1996 | C17: Oct | D17: 22 | E17: 0 | F17: 760 | G17: tier - 3 | H17: tier - 3 | I17: R1013 | M17: 2) Fill in the missing values of ‘month’ with Sep and ‘year’ with its average rounded to the
A18: Id2319 | B18: 1993 | C18: Jun | D18: 28 | E18: 0 | F18: 770 | G18: tier - 3 | H18: tier - 3 | I18: R1013 | M18: nearest integer.
A19: Id2318 | B19: 1996 | C19: Sep | D19: 18 | E19: 0 | F19: 770.38 | G19: tier - 3 | H19: tier - 2 | I19: R1012 | M19: =AVERAGE(B:B) -> 1982.8417 | N19: =ROUND(M19,0) -> 1983
A20: Id2317 | B20: 1995 | C20: Dec | D20: 7 | E20: 0 | F20: 773.54 | G20: tier - 3 | H20: tier - 2 | I20: R1013
A21: Id2316 | B21: 2004 | C21: Oct | D21: 7 | E21: 0 | F21: 830.52 | G21: tier - 3 | H21: tier - 2 | I21: R1011 | M21: 3) Determine the most frequently occurring values in the ‘smoker’, 'Hospital tier' and 'City
A22: Id2315 | B22: 2000 | C22: Nov | D22: 18 | E22: 0 | F22: 865.41 | G22: tier - 3 | H22: tier - 1 | I22: R1013 | M22: tier' columns, and fill in the missing values accordingly.
A23: Id2314 | B23: 1993 | C23: Nov | D23: 27 | E23: 0 | F23: 896.21 | G23: tier - 3 | H23: tier - 1 | I23: R1013 | M23: Hospital tier | O23: City
A24: Id2313 | B24: 1994 | C24: Oct | D24: 30 | E24: 0 | F24: 915.07 | G24: tier - 3 | H24: tier - 1 | I24: R1013 | L24: tire -1 | M24: =COUNTIF(G2:G2344,G2336) -> 309 | O24: =COUNTIF(H2:H2344,H2342) -> 734
A25: Id2312 | B25: 1995 | C25: Oct | D25: 28 | E25: 0 | F25: 928.59 | G25: tier - 3 | H25: tier - 1 | I25: R1013 | L25: tire -2 | M25: =COUNTIF(G2:G2344,G2) -> 1340 | O25: =COUNTIF(H3:H2345,H20) -> 813
A26: Id2311 | B26: 2001 | C26: Aug | D26: 19 | E26: 0 | F26: 964.71 | G26: tier - 3 | H26: tier - 2 | I26: R1013 | L26: tire -3 | M26: =COUNTIF(G3:G2345,G14) -> 694 | O26: =COUNTIF(H4:H2346,H18) -> 795
A27: Id2310 | B27: 1994 | C27: Nov | D27: 22 | E27: 0 | F27: 1006.65 | G27: tier - 3 | H27: tier - 2 | I27: R1013
A28: Id2309 | B28: 2000 | C28: Oct | D28: 9 | E28: 0 | F28: 1012 | G28: tier - 3 | H28: tier - 2 | I28: R1013 | M28: 4) If any 'State ID' values are missing, consider filling them with 'Unknown' or using another appropriate strategy.
A29: Id2308 | B29: 1999 | C29: Aug | D29: 5 | E29: 0 | F29: 1019 | G29: tier - 3 | H29: tier - 2 | I29: R1013
A30: Id2307 | B30: 1995 | C30: Oct | D30: 5 | E30: 0 | F30: 1033.74 | G30: tier - 3 | H30: tier - 1 | I30: R1013 | M30: Data Transformation:
A31: Id2306 | B31: 1994 | C31: Nov | D31: 17 | E31: 0 | F31: 1044 | G31: tier - 3 | H31: tier - 2 | I31: R1013 | M31: 1) Split the ‘names’ column in the “Customer Names” Table into 3 meaningful columns: ‘Title’, ‘First Name’, and ‘Last Name’.
A32: Id2305 | B32: 2002 | C32: Jul | D32: 20 | E32: 0 | F32: 1047 | G32: tier - 3 | H32: tier - 1 | I32: R1013 | M32: splitting completed.
A33: Id2304 | B33: 2002 | C33: Jul | D33: 1 | E33: 0 | F33: 1049 | G33: tier - 3 | H33: tier - 2 | I33: R1012
A34: Id2303 | B34: 1995 | C34: Jun | D34: 1 | E34: 0 | F34: 1056 | G34: tier - 3 | H34: tier - 2 | I34: R1013
A35: Id2302 | B35: 1993 | C35: Sep | D35: 28 | E35: 0 | F35: 1068 | G35: tier - 3 | H35: tier - 1 | I35: R1013
A36: Id2301 | B36: 2004 | C36: Aug | D36: 24 | E36: 0 | F36: 1070 | G36: tier - 3 | H36: tier - 3 | I36: R1013
A37: Id2300 | B37: 1997 | C37: Aug | D37: 13 | E37: 0 | F37: 1071 | G37: tier - 3 | H37: tier - 3 | I37: R1013
A38: Id2299 | B38: 1998 | C38: Dec | D38: 26 | E38: 0 | F38: 1082 | G38: tier - 3 | H38: tier - 2 | I38: R1013
A39: Id2298 | B39: 2002 | C39: Aug | D39: 13 | E39: 0 | F39: 1086 | G39: tier - 3 | H39: tier - 3 | I39: R1013
A40: Id2297 | B40: 2004 | C40: Nov | D40: 12 | E40: 0 | F40: 1121.87 | G40: tier - 3 | H40: tier - 1 | I40: R1013
...
